Workbook

Sheet Menu
A1: Category | B1: Item | C1: Description / Ingredients | D1: Price (₹)
A2: Salads | B2: Greek Salad | C2: Cucumber, Tomato, Bell Pepper, Black Olives, Red Onion, Feta | D2: 349
A3: Salads | B3: Turkish Çoban Salad | C3: Tomato, Cucumber, Onion, Bell Pepper, Parsley, Sumac | D3: 299
A4: Salads | B4: Burrata Caprese | C4: Cherry Tomato, Fresh Basil, Burrata, Balsamic Glaze | D4: 499
A5: Soups | B5: Cream of Mushroom | C5: Mushroom, Garlic, Thyme, Black Pepper | D5: 249
A6: Soups | B6: Roasted Tomato Basil | C6: Roasted Tomato, Basil, Garlic, Parmesan | D6: 249
A7: Soups | B7: Broccoli Parmesan | C7: Broccoli, Garlic, Cream, Parmesan | D7: 249
A8: Soups | B8: Italian Minestrone | C8: Zucchini, Carrot, Beans, Celery, Pasta, Parmesan, Basil | D8: 299
A9: Soups | B9: Turkish Lentil Soup | C9: Red Lentils, Carrot, Onion, Cumin, Paprika, Lemon | D9: 249
A10: Garlic Bread & Turkish Bread | B10: Turkish Simit | C10: Sesame, Turkish White Cheese | D10: 179
A11: Garlic Bread & Turkish Bread | B11: Bazlama | C11: Garlic Butter, Parsley | D11: 199
A12: Garlic Bread & Turkish Bread | B12: Garlic Herb Turkish Bread | C12: Roasted Garlic, Parsley, Oregano, Mozzarella | D12: 249
A13: Garlic Bread & Turkish Bread | B13: Za'atar Turkish Bread | C13: Za'atar, Sesame, EVOO | D13: 249
... A38: Desserts | B38: Chocolate Brownie with Ice Cream | C38: Not listed on menu | D38: 195
A39: Desserts | B39: Ice Cream - Vanilla | D39: 135
A40: Desserts | B40: Ice Cream - Chocolate | D40: 145
A41: Desserts | B41: Ice Cream - Butterscotch | D41: 155
A42: Desserts | B42: Ice Cream - American Nuts | D42: 165
A43: Desserts | B43: Ice Cream - Chocolate Brownie | D43: 175
A44: Moctails | B44: Turkish Pomegranate Fizz | C44: Not listed (menu repeats the name) | D44: 279
A45: Moctails | B45: Istanbul Blue | C45: Blue Curaçao, Lemon, Mint, Soda | D45: 279
A46: Moctails | B46: Mediterranean Sunset | C46: Orange, Cranberry, Grenadine, Lemon | D46: 279
A47: Moctails | B47: Berry Basil Smash | C47: Mixed Berries, Basil, Lemon, Soda | D47: 299
A48: Moctails | B48: Passionfruit Mojito | C48: Passionfruit, Mint, Lime, Soda | D48: 299
A49: Carbonated | B49: Sprite | D49: 99
A50: Carbonated | B50: Fanta | D50: 99
A51: Carbonated | B51: Coke | D51: 99
A52: Carbonated | B52: Zero Coke | D52: 99
A53: Carbonated | B53: Thums Up | D53: 129
A54: Carbonated | B54: Tonic Water | D54: 199
A55: Carbonated | B55: Ginger Ale | D55: 60
A56: Carbonated | B56: RedBull Energy | D56: 125
A57: Cold Coffee | B57: Classic Cold Coffee | C57: Espresso, Chilled Milk, Ice | D57: 229
A58: Cold Coffee | B58: Mocha Cold Coffee | C58: Espresso, Chocolate, Milk, Ice | D58: 269
A59: Cold Coffee | B59: Hazelnut Cold Coffee | C59: Espresso, Hazelnut, Milk, Ice | D59: 299
A60: Cold Coffee | B60: Vanilla Cream Cold Coffee | C60: Espresso, Vanilla, Milk, Cream | D60: 299
A61: Angara / Turkish Coffee | B61: Angara Turkish Coffee | C61: Turkish Delight | D61: 199
A62: Angara / Turkish Coffee | B62: Turkish Cold Coffee | C62: Turkish Coffee, Milk, Ice | D62: 299
C64: Total items | D64: =COUNTA(B2:B62) -> 61
C65: Average price | D65: =AVERAGE(D2:D62) -> 306.59016
...

Sheet Summary
A1: Category | B1: Items | C1: Min Price (₹) | D1: Max Price (₹)
A2: Salads | B2: =COUNTIF(Menu!$A$2:$A$62,A2) -> 3 | C2: =_xlfn.MINIFS(Menu!$D$2:$D$62,Menu!$A$2:$A$62,A2) -> 299 | D2: =_xlfn.MAXIFS(Menu!$D$2:$D$62,Menu!$A$2:$A$62,A2) -> 499
A3: Soups | B3: =COUNTIF(Menu!$A$2:$A$62,A3) -> 5 | C3: =_xlfn.MINIFS(Menu!$D$2:$D$62,Menu!$A$2:$A$62,A3) -> 249 | D3: =_xlfn.MAXIFS(Menu!$D$2:$D$62,Menu!$A$2:$A$62,A3) -> 299
A4: Garlic Bread & Turkish Bread | B4: =COUNTIF(Menu!$A$2:$A$62,A4) -> 5 | C4: =_xlfn.MINIFS(Menu!$D$2:$D$62,Menu!$A$2:$A$62,A4) -> 179 | D4: =_xlfn.MAXIFS(Menu!$D$2:$D$62,Menu!$A$2:$A$62,A4) -> 299
A5: Turkish Pide | B5: =COUNTIF(Menu!$A$2:$A$62,A5) -> 5 | C5: =_xlfn.MINIFS(Menu!$D$2:$D$62,Menu!$A$2:$A$62,A5) -> 399 | D5: =_xlfn.MAXIFS(Menu!$D$2:$D$62,Menu!$A$2:$A$62,A5) -> 499
A6: Pasta | B6: =COUNTIF(Menu!$A$2:$A$62,A6) -> 5 | C6: =_xlfn.MINIFS(Menu!$D$2:$D$62,Menu!$A$2:$A$62,A6) -> 349 | D6: =_xlfn.MAXIFS(Menu!$D$2:$D$62,Menu!$A$2:$A$62,A6) -> 499
A7: Italian Neapolitan Pizzas | B7: =COUNTIF(Menu!$A$2:$A$62,A7) -> 5 | C7: =_xlfn.MINIFS(Menu!$D$2:$D$62,Menu!$A$2:$A$62,A7) -> 499 | D7: =_xlfn.MAXIFS(Menu!$D$2:$D$62,Menu!$A$2:$A$62,A7) -> 649
A8: Turkish Pizza / Lahmacun | B8: =COUNTIF(Menu!$A$2:$A$62,A8) -> 5 | C8: =_xlfn.MINIFS(Menu!$D$2:$D$62,Menu!$A$2:$A$62,A8) -> 349 | D8: =_xlfn.MAXIFS(Menu!$D$2:$D$62,Menu!$A$2:$A$62,A8) -> 499
A9: Desserts | B9: =COUNTIF(Menu!$A$2:$A$62,A9) -> 9 | C9: =_xlfn.MINIFS(Menu!$D$2:$D$62,Menu!$A$2:$A$62,A9) -> 135 | D9: =_xlfn.MAXIFS(Menu!$D$2:$D$62,Menu!$A$2:$A$62,A9) -> 349
A10: Moctails | B10: =COUNTIF(Menu!$A$2:$A$62,A10) -> 5 | C10: =_xlfn.MINIFS(Menu!$D$2:$D$62,Menu!$A$2:$A$62,A10) -> 279 | D10: =_xlfn.MAXIFS(Menu!$D$2:$D$62,Menu!$A$2:$A$62,A10) -> 299
A11: Carbonated | B11: =COUNTIF(Menu!$A$2:$A$62,A11) -> 8 | C11: =_xlfn.MINIFS(Menu!$D$2:$D$62,Menu!$A$2:$A$62,A11) -> 60 | D11: =_xlfn.MAXIFS(Menu!$D$2:$D$62,Menu!$A$2:$A$62,A11) -> 199
A12: Cold Coffee | B12: =COUNTIF(Menu!$A$2:$A$62,A12) -> 4 | C12: =_xlfn.MINIFS(Menu!$D$2:$D$62,Menu!$A$2:$A$62,A12) -> 229 | D12: =_xlfn.MAXIFS(Menu!$D$2:$D$62,Menu!$A$2:$A$62,A12) -> 299
A13: Angara / Turkish Coffee | B13: =COUNTIF(Menu!$A$2:$A$62,A13) -> 2 | C13: =_xlfn.MINIFS(Menu!$D$2:$D$62,Menu!$A$2:$A$62,A13) -> 199 | D13: =_xlfn.MAXIFS(Menu!$D$2:$D$62,Menu!$A$2:$A$62,A13) -> 299
A14: Total | B14: =SUM(B2:B13) -> 61

Sheet Ingredients
A1: Group | B1: Available Ingredients
A2: Toppings | B2: Fresh Tomato, Cherry Tomato, Bell Pepper, Jalapeno, Green Chilli, Black Olives, Mushroom, Tandoori Paneer, Baby Corn, Red Onion, Garlic, Fresh Basil, Parsley, Spinach, Thyme, Oregano, Za'atar, Fresh Mint, Lemon
A3: Cheese | B3: Mozzarella, Fior di Latte, Burrata, Parmesan, Turkish White Cheese, Feta
A4: Sauces and Finishes | B4: Tomato Sauce, Basil Pesto, White Sauce, Pink Sauce, Tandoori Sauce, Extra Virgin Olive Oil, Chilli Oil, Truffle Oil, Balsamic Glaze
A5: Sugar | B5: Regular White Sugar, Brown Sugar
